Workbook

Sheet Auditoría
A1: Nro. Orden | B1: Tipo de orden | C1: Centros de costos | D1: Estado Orden | E1: Contabilizada | F1: Fecha de la orden | G1: Status de documento | H1: Equipo | I1: Nombre Equipo | J1: Tarea | K1: Control | L1: Repuestas. | M1: Estado Tarea | N1: Tipo de Hallazgo | O1: Detalle | P1: Resultado IA | Q1: Material Relacionado | R1: Confianza IA | S1: Justificación IA | T1: Descarga | U1: Estados Control | V1: Estados OK
A2: 38411 | B2: Correctivo | C2: MNZA | D2: Liberada | E2: No | F2: 46236 | G2: O | H2: LUW863 | I2: ACOPLADO BARANDA VOLC. 3 EJES | J2: Cambiar Cubierta 3DI | K2: =VLOOKUP(A2,[1]Auditoría!$A$2:$K$69,11,FALSE) -> Falta Consumo | M2: Terminada | N2: 3) Planificado sin Salida física (Salidas = 0) | O2: Materiales planificados con Salida Cero: RECAPADO NEUMATICO 295 | T2: 46254 | U2: 46248
A3: 38411 | B3: Correctivo | C3: MNZA | D3: Liberada | E3: No | F3: 46236 | G3: O | H3: LUW863 | I3: ACOPLADO BARANDA VOLC. 3 EJES | J3: Cambiar Cubierta 3II | K3: =VLOOKUP(A3,[1]Auditoría!$A$2:$K$69,11,FALSE) -> Falta Consumo | M3: Terminada | N3: 3) Planificado sin Salida física (Salidas = 0) | O3: Materiales planificados con Salida Cero: RECAPADO NEUMATICO 295 | T3: 46254 | U3: 46248
A4: 38411 | B4: Correctivo | C4: MNZA | D4: Liberada | E4: No | F4: 46236 | G4: O | H4: LUW863 | I4: ACOPLADO BARANDA VOLC. 3 EJES | J4: Cambiar Cubierta 3DE | K4: =VLOOKUP(A4,[1]Auditoría!$A$2:$K$69,11,FALSE) -> Falta Consumo | M4: Terminada | N4: 3) Planificado sin Salida física (Salidas = 0) | O4: Materiales planificados con Salida Cero: RECAPADO NEUMATICO 295 | T4: 46254 | U4: 46248
A5: 38529 | B5: Correctivo | C5: MNZA | D5: Liberada | E5: No | F5: 46236 | G5: O | H5: LTS288 | I5: ATEGO 1725 | J5: Colocar inyectores y bomba inyectora | M5: Terminada | N5: 1) Orden sin repuestos asignados | O5: Ningún material cargado en la orden | T5: 46254 | U5: 46254
A6: 38534 | B6: Correctivo | C6: SRAF | D6: Liberada | E6: No | F6: 46238 | G6: O | H6: MQU466 | I6: SCANIA P360 A6X2 | J6: Cambiar junta de compresor de aire | K6: =VLOOKUP(A6,[1]Auditoría!$A$2:$K$69,11,FALSE) -> Falta Material | M6: Terminada | N6: 1) Orden sin repuestos asignados | O6: Ningún material cargado en la orden | T6: 46254 | U6: 46248
A7: 38989 | B7: Auxilios | C7: SRAF | D7: Liberada | E7: No | F7: 46238 | G7: O | H7: AE812EN | I7: SCANIA P410 A6X2 | J7: Cambiar ruleman de rueda trasera izquierda | K7: =VLOOKUP(A7,[1]Auditoría!$A$2:$K$69,11,FALSE) -> Falta Material | M7: Terminada | N7: 1) Orden sin repuestos asignados | O7: Ningún material cargado en la orden | T7: 46254 | U7: 46248
A8: 38557 | B8: Correctivo | C8: SRAF | D8: Liberada | E8: No | F8: 46239 | G8: O | H8: IDX164 | I8: AXOR 1933 | J8: Sin tarea que requiera material | K8: =VLOOKUP(A8,[1]Auditoría!$A$2:$K$69,11,FALSE) -> Falta Tarea | M8: N/A | N8: 4) Repuesto sin tarea (IA) | O8: Material "ESCOBILLA LIMPIA PARABRISAS 26" (650MM) - BOSCH (B162)" (Salidas: 2) cargado pero ninguna tarea requiere material | T8: 46254 | U8: 46248
A9: 38557 | B9: Correctivo | C9: SRAF | D9: Liberada | E9: No | F9: 46239 | G9: O | H9: IDX164 | I9: AXOR 1933 | J9: Sin tarea que requiera material | K9: =VLOOKUP(A9,[1]Auditoría!$A$2:$K$69,11,FALSE) -> Falta Tarea | M9: N/A | N9: 4) Repuesto sin tarea (IA) | O9: Material "RELAY DE LUCES INDICADORAS MB AXOR 1933 (A 003 544 61 32) ORIGINAL" (Salidas: 1) cargado pero ninguna tarea requiere material | T9: 46254 | U9: 46248
A10: 38574 | B10: Preventivo | C10: CIUD | D10: Liberada | E10: No | F10: 46239 | G10: O | H10: AF743LB | I10: ATEGO 1729 | J10: Cambiar filtro de aire | K10: =VLOOKUP(A10,[1]Auditoría!$A$2:$K$69,11,FALSE) -> Falta Consumo | M10: Terminada | N10: 3) Planificado sin Salida física (Salidas = 0) | O10: Materiales planificados con Salida Cero: FILTRO DE AIRE MB 2426/AXOR 1933 - MANN C28 1012 | T10: 46254 | U10: 46248
A11: 38597 | B11: Correctivo | C11: SRAF | D11: Liberada | E11: No | F11: 46240 | G11: O | H11: HRJ002 | I11: 1318 | J11: Sin tarea que requiera material | K11: =VLOOKUP(A11,[1]Auditoría!$A$2:$K$69,11,FALSE) -> Falta Tarea | M11: N/A | N11: 4) Repuesto sin tarea (IA) | O11: Material "MICA BAIML 1035 COLOR CRISTAL (LED)" (Salidas: 2) cargado pero ninguna tarea requiere material | T11: 46254 | U11: 46248
A12: 38597 | B12: Correctivo | C12: SRAF | D12: Liberada | E12: No | F12: 46240 | G12: O | H12: HRJ002 | I12: 1318 | J12: Sin tarea que requiera material | K12: =VLOOKUP(A12,[1]Auditoría!$A$2:$K$69,11,FALSE) -> Falta Tarea | M12: N/A | N12: 4) Repuesto sin tarea (IA) | O12: Material "LAMPARA 24V 5W (C/CULOTE) - NEOLUX" (Salidas: 4) cargado pero ninguna tarea requiere material | T12: 46254 | U12: 46248
A13: 38597 | B13: Correctivo | C13: SRAF | D13: Liberada | E13: No | F13: 46240 | G13: O | H13: HRJ002 | I13: 1318 | J13: Sin tarea que requiera material | K13: =VLOOKUP(A13,[1]Auditoría!$A$2:$K$69,11,FALSE) -> Falta Tarea | M13: N/A | N13: 4) Repuesto sin tarea (IA) | O13: Material "FARO COLGANTE SIMPLE 1035/6" (Salidas: 4) cargado pero ninguna tarea requiere material | T13: 46254 | U13: 46248
A14: 38597 | B14: Correctivo | C14: SRAF | D14: Liberada | E14: No | F14: 46240 | G14: O | H14: HRJ002 | I14: 1318 | J14: Sin tarea que requiera material | K14: =VLOOKUP(A14,[1]Auditoría!$A$2:$K$69,11,FALSE) -> Falta Tarea | M14: N/A | N14: 4) Repuesto sin tarea (IA) | O14: Material "LAMPARA 24V PY21W" (Salidas: 6) cargado pero ninguna tarea requiere material | T14: 46254 | U14: 46248
A15: 38600 | B15: Correctivo | C15: CIUD | D15: Liberada | E15: No | F15: 46240 | G15: O | H15: AF461DB | I15: PALETERO S.PA.3E.71 2+1 | J15: Múltiples repuestos | K15: =VLOOKUP(A15,[1]Auditoría!$A$2:$K$69,11,FALSE) -> Ok Contabilizar Si Corresponde | M15: Revisión | N15: 5) Materiales Repetidos | O15: Se cargó el mismo repuesto varias veces en la orden: 'REMACHE POP ALUMINIO DE 5MM DIAMETRO X 20MM LARGO' (2 veces). Revisar posibles duplicados. | T15: 46254 | U15: 46248
A16: 38600 | B16: Correctivo | C16: CIUD | D16: Liberada | E16: No | F16: 46240 | G16: O | H16: AF461DB | I16: PALETERO S.PA.3E.71 2+1 | J16: Sin tarea asociada | K16: =VLOOKUP(A16,[1]Auditoría!$A$2:$K$69,11,FALSE) -> Ok Contabilizar Si Corresponde | M16: N/A | N16: 4) Repuesto sin tarea (IA) | O16: Material "REMACHE POP ALUMINIO DE 5MM DIAMETRO X 20MM LARGO" (Salidas: 20) no coincide con ninguna tarea de la orden | T16: 46254 | U16: 46248
A17: 38600 | B17: Correctivo | C17: CIUD | D17: Liberada | E17: No | F17: 46240 | G17: O | H17: AF461DB | I17: PALETERO S.PA.3E.71 2+1 | J17: Sin tarea asociada | K17: =VLOOKUP(A17,[1]Auditoría!$A$2:$K$69,11,FALSE) -> Ok Contabilizar Si Corresponde | M17: N/A | N17: 4) Repuesto sin tarea (IA) | O17: Material "REMACHE POP ALUMINIO DE 5MM DIAMETRO X 20MM LARGO" (Salidas: 5) no coincide con ninguna tarea de la orden | T17: 46254 | U17: 46248
A18: 38608 | B18: Correctivo | C18: SRAF | D18: Liberada | E18: No | F18: 46240 | G18: O | H18: JHD034 | I18: 16-BDAS. VOLC. 3 EJES | J18: Engrase Completo | K18: =VLOOKUP(A18,[1]Auditoría!$A$2:$K$69,11,FALSE) -> Falta Material | M18: No iniciada | N18: 2) Falta material (IA) | O18: Tarea de lubricación sin material de grasa, aceite o refrigerante en la orden | T18: 46254 | U18: 46248
A19: 38608 | B19: Correctivo | C19: SRAF | D19: Liberada | E19: No | F19: 46240 | G19: O | H19: JHD034 | I19: 16-BDAS. VOLC. 3 EJES | J19: Sin tarea asociada | K19: =VLOOKUP(A19,[1]Auditoría!$A$2:$K$69,11,FALSE) -> Ok Contabilizar Si Corresponde | M19: N/A | N19: 4) Repuesto sin tarea (IA) | O19: Material "ACOPLE RAPIDO RECTO DE 10MM" (Salidas: 1) no coincide con ninguna tarea de la orden | T19: 46254 | U19: 46248
A20: 38610 | B20: Correctivo | C20: SRAF | D20: Liberada | E20: No | F20: 46240 | G20: O | H20: OAF642 | I20: G310 | J20: Agregar Aceite (Tractor) | K20: =VLOOKUP(A20,[1]Auditoría!$A$2:$K$69,11,FALSE) -> Falta Material | M20: No iniciada | N20: 1) Orden sin repuestos asignados | O20: Ningún material cargado en la orden | T20: 46254 | U20: 46248
A21: 38610 | B21: Correctivo | C21: SRAF | D21: Liberada | E21: No | F21: 46240 | G21: O | H21: OAF642 | I21: G310 | J21: Engrase Completo | K21: =VLOOKUP(A21,[1]Auditoría!$A$2:$K$69,11,FALSE) -> Falta Material | M21: No iniciada | N21: 1) Orden sin repuestos asignados | O21: Ningún material cargado en la orden | T21: 46254 | U21: 46248
A22: 38612 | B22: Correctivo | C22: SRAF | D22: Liberada | E22: No | F22: 46240 | G22: O | H22: OAF643 | I22: G310 | J22: Agregar Aceite (Tractor) | K22: =VLOOKUP(A22,[1]Auditoría!$A$2:$K$69,11,FALSE) -> Falta Material | M22: No iniciada | N22: 1) Orden sin repuestos asignados | O22: Ningún material cargado en la orden | T22: 46254 | U22: 46248
A23: 38612 | B23: Correctivo | C23: SRAF | D23: Liberada | E23: No | F23: 46240 | G23: O | H23: OAF643 | I23: G310 | J23: Engrase Completo | K23: =VLOOKUP(A23,[1]Auditoría!$A$2:$K$69,11,FALSE) -> Falta Material | M23: No iniciada | N23: 1) Orden sin repuestos asignados | O23: Ningún material cargado en la orden | T23: 46254 | U23: 46248
A24: 38936 | B24: Correctivo | C24: CIUD | D24: Liberada | E24: No | F24: 46240 | G24: O | H24: AD426IJ | I24: AXOR 2541 | J24: Engraso Plato | K24: =VLOOKUP(A24,[1]Auditoría!$A$2:$K$69,11,FALSE) -> Falta Consumo | M24: Terminada | N24: 3) Planificado sin Salida física (Salidas = 0) | O24: Material de lubricante planificado con Salida Cero: GRASA 62 X 20 KG | T24: 46254 | U24: 46248
A25: 39113 | B25: Correctivo | C25: CIUD | D25: Liberada | E25: No | F25: 46241 | G25: O | H25: AD426HX | I25: AXOR 2541 | J25: Cambiar comando levanta vidrio | K25: =VLOOKUP(A25,[1]Auditoría!$A$2:$K$69,11,FALSE) -> Falta Consumo | M25: Terminada | N25: 3) Planificado sin Salida física (Salidas = 0) | O25: Materiales planificados con Salida Cero: COMANDO ALZA CRISTALES MB AXOR (A 005 545 39 13) ORIGINAL | T25: 46254 | U25: 46248
A26: 38974 | B26: Correctivo | C26: MNZA | D26: Liberada | E26: No | F26: 46243 | G26: O | H26: HRJ003 | I26: 1318 | J26: Sin tarea asociada | K26: =VLOOKUP(A26,[1]Auditoría!$A$2:$K$69,11,FALSE) -> Ok | M26: N/A | N26: 4) Repuesto sin tarea (IA) | O26: Material "SILOC FORMADOR DE JUNTA 8600 X 98GR" (Salidas: 1) no coincide con ninguna tarea de la orden | T26: 46254 | U26: 46248
A27: 39128 | B27: Correctivo | C27: CIUD | D27: Liberada | E27: No | F27: 46243 | G27: O | H27: AF066NS | I27: TECTOR EVO 170E28 | J27: Cambiar Rueda Completa C/Llanta Delantera Der | K27: =VLOOKUP(A27,[1]Auditoría!$A$2:$K$69,11,FALSE) -> Falta Consumo | M27: Terminada | N27: 3) Planificado sin Salida física (Salidas = 0) | O27: Materiales planificados con Salida Cero: CUBIERTA LINEAL 275 R22.5 - FATE | T27: 46254 | U27: 46248
A28: 38985 | B28: Correctivo | C28: SRAF | D28: Liberada | E28: No | F28: 46244 | G28: O | H28: KUF609 | I28: AXOR 1933 | J28: Sin tarea que requiera material | K28: =VLOOKUP(A28,[1]Auditoría!$A$2:$K$69,11,FALSE) -> Falta Tarea | M28: N/A | N28: 4) Repuesto sin tarea (IA) | O28: Material "CONECTOR BOMBA DE AGUA 904/906 MB 1624/1725 (A 936 203 33 36) ORIGINAL" (Salidas: 1) cargado pero ninguna tarea requiere material | T28: 46254 | U28: 46252
A29: 38986 | B29: Correctivo | C29: SRAF | D29: Liberada | E29: No | F29: 46244 | G29: O | H29: FQT894 | I29: 1620 | J29: Sin tarea que requiera material | K29: =VLOOKUP(A29,[1]Auditoría!$A$2:$K$69,11,FALSE) -> Falta Tarea | M29: N/A | N29: 4) Repuesto sin tarea (IA) | O29: Material "CONECTOR BOMBA DE AGUA 904/906 MB 1624/1725 (A 936 203 33 36) ORIGINAL" (Salidas: 1) cargado pero ninguna tarea requiere material | T29: 46254 | U29: 46252
A30: 38992 | B30: Correctivo | C30: SRAF | D30: Liberada | E30: No | F30: 46244 | H30: INSUMOS SRF | I30: INSUMOS SAN RAFAEL | J30: Sin tarea que requiera material | K30: =VLOOKUP(A30,[1]Auditoría!$A$2:$K$69,11,FALSE) -> Ok Revisar tipo OM | M30: N/A | N30: 4) Repuesto sin tarea (IA) | O30: Material "LIMPIA CONTACTOS EN AEROSOL 440 ML – CONTACMATIC BIO DELTA" (Salidas: 1) cargado pero ninguna tarea requiere material | T30: 46254 | U30: 46252
A31: 38992 | B31: Correctivo | C31: SRAF | D31: Liberada | E31: No | F31: 46244 | H31: INSUMOS SRF | I31: INSUMOS SAN RAFAEL | J31: Sin tarea que requiera material | K31: =VLOOKUP(A31,[1]Auditoría!$A$2:$K$69,11,FALSE) -> Ok Revisar tipo OM | M31: N/A | N31: 4) Repuesto sin tarea (IA) | O31: Material "REJILLA TRAMA ANCHA - SEMI PASADA" (Salidas: 6) cargado pero ninguna tarea requiere material | T31: 46254 | U31: 46252
A32: 38992 | B32: Correctivo | C32: SRAF | D32: Liberada | E32: No | F32: 46244 | H32: INSUMOS SRF | I32: INSUMOS SAN RAFAEL | J32: Sin tarea que requiera material | K32: =VLOOKUP(A32,[1]Auditoría!$A$2:$K$69,11,FALSE) -> Ok Revisar tipo OM | M32: N/A | N32: 4) Repuesto sin tarea (IA) | O32: Material "PINCEL DE 25MM (1")" (Salidas: 1) cargado pero ninguna tarea requiere material | T32: 46254 | U32: 46252
A33: 38993 | B33: Auxilios | C33: MNZA | D33: Liberada | E33: No | F33: 46244 | G33: O | H33: AB696BS | I33: ATRON 1735 45 | J33: Sin tarea asociada | K33: =VLOOKUP(A33,[1]Auditoría!$A$2:$K$69,11,FALSE) -> Ok | M33: N/A | N33: 4) Repuesto sin tarea (IA) | O33: Material "CAÑO POLIAMIDA TECALAN DE 10MM X MTS" (Salidas: 0.2) no coincide con ninguna tarea de la orden | T33: 46254 | U33: 46248
A34: 39004 | B34: Insumo | C34: MNZA | D34: Liberada | E34: No | F34: 46244 | H34: ESTRUCTURA MZ | I34: ESTRUCTURA MENDOZA | J34: Sin tarea que requiera material | K34: (Ver es estructura o Insumo) | M34: N/A | N34: 4) Repuesto sin tarea (IA) | O34: Material "KIT DE REPARACION DE COMPRESOR DE AIRE (85MM) MB ATEGO 1725/1419 - PELLACANI (2003111)" (Salidas: 2) cargado pero ninguna tarea requiere material | T34: 46254 | U34: 46248
A35: 39004 | B35: Insumo | C35: MNZA | D35: Liberada | E35: No | F35: 46244 | H35: ESTRUCTURA MZ | I35: ESTRUCTURA MENDOZA | J35: Sin tarea que requiera material | K35: (Ver es estructura o Insumo) | M35: N/A | N35: 4) Repuesto sin tarea (IA) | O35: Material "THINNER X 18LT" (Salidas: 14) cargado pero ninguna tarea requiere material | T35: 46254 | U35: 46248
A36: 39010 | B36: Correctivo | C36: SRAF | D36: Liberada | E36: No | F36: 46244 | G36: O | H36: IBB073 | I36: S PA 3E 71 | J36: Engrase Completo | K36: =VLOOKUP(A36,[1]Auditoría!$A$2:$K$69,11,FALSE) -> Falta Material | M36: No iniciada | N36: 1) Orden sin repuestos asignados | O36: Ningún material cargado en la orden | T36: 46254 | U36: 46248
A37: 39151 | B37: Correctivo | C37: CIUD | D37: Liberada | E37: No | F37: 46244 | G37: O | H37: AD426IJ | I37: AXOR 2541 | J37: Cambiar lampara h3 24v | K37: =VLOOKUP(A37,[1]Auditoría!$A$2:$K$69,11,FALSE) -> Falta Consumo | M37: Terminada | N37: 3) Planificado sin Salida física (Salidas = 0) | O37: Materiales planificados con Salida Cero: LAMPARA H3 24V | T37: 46254 | U37: 46248
A38: 39322 | B38: Correctivo | C38: MNZA | D38: Liberada | E38: No | F38: 46245 | G38: O | H38: GYB034 | I38: 710 | J38: Agregar liquido refrigerante | K38: =VLOOKUP(A38,[1]Auditoría!$A$2:$K$69,11,FALSE) -> Falta Consumo | M38: No iniciada | N38: 3) Planificado sin Salida física (Salidas = 0) | O38: Materiales planificados con Salida Cero: LIQUIDO REFRIGERANTE 50/50 X 1000LTS, LAMPARA 12V 21W UN POLO, BOMBA DE AGUA (OM364) MB 710 (A 364 200 00 01) - VMG (BA1239), LAMPARA 12V 5W (S/CULOTE) | T38: 46254 | U38: 46253
A39: 39322 | B39: Correctivo | C39: MNZA | D39: Liberada | E39: No | F39: 46245 | G39: O | H39: GYB034 | I39: 710 | J39: Cambiar bomba de agua | K39: =VLOOKUP(A39,[1]Auditoría!$A$2:$K$69,11,FALSE) -> Falta Consumo | M39: No iniciada | N39: 3) Planificado sin Salida física (Salidas = 0) | O39: Materiales planificados con Salida Cero: LIQUIDO REFRIGERANTE 50/50 X 1000LTS, LAMPARA 12V 21W UN POLO, BOMBA DE AGUA (OM364) MB 710 (A 364 200 00 01) - VMG (BA1239), LAMPARA 12V 5W (S/CULOTE) | T39: 46254 | U39: 46253
A40: 39322 | B40: Correctivo | C40: MNZA | D40: Liberada | E40: No | F40: 46245 | G40: O | H40: GYB034 | I40: 710 | J40: Cambiar lampara 3w 24v | K40: =VLOOKUP(A40,[1]Auditoría!$A$2:$K$69,11,FALSE) -> Falta Consumo | M40: No iniciada | N40: 3) Planificado sin Salida física (Salidas = 0) | O40: Materiales planificados con Salida Cero: LIQUIDO REFRIGERANTE 50/50 X 1000LTS, LAMPARA 12V 21W UN POLO, BOMBA DE AGUA (OM364) MB 710 (A 364 200 00 01) - VMG (BA1239), LAMPARA 12V 5W (S/CULOTE) | T40: 46254 | U40: 46253
...
