Workbook

Sheet Auditoría
A1: Nro. Orden | B1: Tipo de orden | C1: Centros de costos | D1: Contabilizada | E1: Fecha de la orden | F1: Status de documento | G1: Equipo | H1: Nombre Equipo | I1: Tarea | J1: Control | K1: Estado Tarea | L1: Tipo de Hallazgo | M1: Detalle | N1: Descarga | O1: Estados Control | P1: Estados OK
A2: 35573 | B2: Correctivo | C2: BSAS | D2: No | E2: 46176 | F2: O | G2: AF066NT | H2: TECTOR EVO 170E28 | I2: Se Colocó Portadocumento Nuevo | J2: OK Contabilizar | K2: Terminada | L2: 2) Desconexión de material (Falta 'PORTADOCUMENTOS') | M2: Materiales cargados no coinciden: LAMPARA 24V 5W (C/CULOTE) - NEOLUX | N2: 46234
A3: 36119 | B3: Correctivo | C3: SRAF | D3: No | E3: 46177 | F3: O | G3: OAF635 | H3: 16-BDAS. VOLC. 3 EJES | I3: Cambiar rueda completa remolque en taller | J3: =VLOOKUP(A3,[1]Auditoría!$A$2:$J$312,10,FALSE) -> Falta Consumos | K3: Terminada | L3: 3) Planificado sin Salida física (Salidas = 0) | M3: Materiales planificados con Salida Cero: RECAPADO NEUMATICO 295 | N3: 46234 | O3: 46231
A4: 35407 | B4: Correctivo | C4: CIUD | D4: No | E4: 46180 | F4: O | G4: HQM968 | H4: 1318 | I4: Cambiar Maquina levanta Cristal Der | J4: =VLOOKUP(A4,[1]Auditoría!$A$2:$J$312,10,FALSE) -> Falta Material | K4: Terminada | L4: 2) Desconexión de material (Falta 'NEUMATICO', 'RUEDA') | M4: Materiales cargados no coinciden: LAMPARA 24V 5W (C/CULOTE) - NEOLUX, MANIJA ALZA CRISTALES MB 1720/1620/1634/1318 (A 688 760 70 02) - RGL (2146G), TORNILLO FIX PARA MADERA 6X40, TORNILLO PUNTA DE MECHA 8 x 3/4, PORTA LAMPARA PARA FARO COLGANTE DOBLE/SIMPLE 1035/6 (AMBAR/AMBAR) SIN CABLE - BAIML, COLIZA IZQ AXOR/ATEGO (A 958 722 00 25) - LISGOM, MAQUINA ALZA CRISTALES DER MB 1318/1624/1620/1720 (A 688 720 76 46) - RGL (56611D), BALDE GRASA LUBRIGON X 20 KG, CINTA DE TELA SUJETA CABLES 19MM X ROLLO, ACEITE 15W40 XV300 X 205LT (TAMBOR), TORNILLO PUNTA MECHA CABEZA HEXAGONAL 5/16 X 1" X UN | N4: 46234 | O4: 46231
A5: 35828 | B5: Correctivo | C5: SRAF | D5: No | E5: 46188 | F5: O | G5: AD267VH | H5: FORD CARGO 1519-48 | I5: Cambiar codo de admision del turbo | J5: =VLOOKUP(A5,[1]Auditoría!$A$2:$J$312,10,FALSE) -> OK, Contabilizar | K5: Terminada | L5: 2) Desconexión de material (Falta 'MANGUERA', 'BULBO') | M5: Materiales cargados no coinciden: FILTRO DE AIRE FORD CARGO 1519/48 - WIX WA 10529, CODO DE ENTREDA DE TOMA DE AIRE FORD CARGO 1519/48 - RESERPLASTIC (001222) | N5: 46234 | O5: 46231 | P5: OK
A6: 36086 | B6: Correctivo | C6: BSAS | D6: No | E6: 46189 | F6: O | G6: OJG072 | H6: 32-CORT. LAT. 3 EJES-1 | I6: Cambio Lampara de Posicion | J6: =VLOOKUP(A6,[1]Auditoría!$A$2:$J$312,10,FALSE) -> Falta Consumos | K6: Terminada | L6: 3) Planificado sin Salida física (Salidas = 0) | M6: Materiales planificados con Salida Cero: LAMPARA 24V 5W (S/CULOTE) - NEOLUX | N6: 46234 | O6: 46231
A7: 36401 | B7: Correctivo | C7: BSAS | D7: No | E7: 46189 | F7: O | G7: OJG063 | H7: ATRON 1720 | I7: Cambiar Lamparas 24V 21/5w Varias | J7: =VLOOKUP(A7,[1]Auditoría!$A$2:$J$312,10,FALSE) -> Falta Salia Material | K7: Terminada | L7: 3) Planificado sin Salida física (Salidas = 0) | M7: Materiales planificados con Salida Cero: LAMPARA 12V 21W/5W (DOS POLOS) | N7: 46234 | O7: 46231
A8: 36002 | B8: Correctivo | C8: CIUD | D8: No | E8: 46191 | F8: O | G8: AF371BG | H8: PALETERO S.PA.3E.71 2+1 | I8: Cambiar Sensor de Valvulas de 6 Vias | J8: =VLOOKUP(A8,[1]Auditoría!$A$2:$J$312,10,FALSE) -> Falta Material | K8: Terminada | L8: 1) Orden sin repuestos asignados | M8: Ningún material cargado en la orden | N8: 46234 | O8: 46231
A9: 36436 | B9: Correctivo | C9: BSAS | D9: No | E9: 46194 | F9: O | G9: HQM968 | H9: 1318 | I9: Cambiar lamparas | J9: =VLOOKUP(A9,[1]Auditoría!$A$2:$J$312,10,FALSE) -> Falta Consumos | K9: Terminada | L9: 3) Planificado sin Salida física (Salidas = 0) | M9: Materiales planificados con Salida Cero: LAMPARA 24V 21W | N9: 46234 | O9: 46231
A10: 36348 | B10: Correctivo | C10: CIUD | D10: No | E10: 46197 | F10: O | G10: KMF921 | H10: FTHDCFW3 | I10: Colocar chapa Semi C/Remaches Lateral Izquierdo | J10: =VLOOKUP(A10,[1]Auditoría!$A$2:$J$312,10,FALSE) -> OK, Contabilizar | K10: Terminada | L10: 2) Desconexión de material (Falta 'TORNILO') | M10: Materiales cargados no coinciden: SIKAFLEX 221 x 600ml (SALCHICHA), CHAPA GALVANIZADA 0.30X16.50 MTS (ESPESOR 0.7) X UN, CHAPA GALVANIZADA 0.30X16.50 MTS (ESPESOR 0.7) X UN, SIKAFLEX 221 x 600ml (SALCHICHA) | N10: 46234 | O10: 46231 | P10: OK
A11: 36348 | B11: Correctivo | C11: CIUD | D11: No | E11: 46197 | F11: O | G11: KMF921 | H11: FTHDCFW3 | I11: Colocar chapa Semi C/Remaches Lateral Derecho | J11: =VLOOKUP(A11,[1]Auditoría!$A$2:$J$312,10,FALSE) -> OK, Contabilizar | K11: Terminada | L11: 2) Desconexión de material (Falta 'TORNILO') | M11: Materiales cargados no coinciden: SIKAFLEX 221 x 600ml (SALCHICHA), CHAPA GALVANIZADA 0.30X16.50 MTS (ESPESOR 0.7) X UN, CHAPA GALVANIZADA 0.30X16.50 MTS (ESPESOR 0.7) X UN, SIKAFLEX 221 x 600ml (SALCHICHA) | N11: 46234 | O11: 46231 | P11: OK
A12: 36348 | B12: Correctivo | C12: CIUD | D12: No | E12: 46197 | F12: O | G12: KMF921 | H12: FTHDCFW3 | I12: Limpio Laterales de interior de Semi para Colocar Silicona | J12: =VLOOKUP(A12,[1]Auditoría!$A$2:$J$312,10,FALSE) -> OK, Contabilizar | K12: Terminada | L12: 2) Desconexión de material (Falta 'SILICONA') | M12: Materiales cargados no coinciden: SIKAFLEX 221 x 600ml (SALCHICHA), CHAPA GALVANIZADA 0.30X16.50 MTS (ESPESOR 0.7) X UN, CHAPA GALVANIZADA 0.30X16.50 MTS (ESPESOR 0.7) X UN, SIKAFLEX 221 x 600ml (SALCHICHA) | N12: 46234 | O12: 46231 | P12: OK
A13: 36355 | B13: Correctivo | C13: CIUD | D13: No | E13: 46198 | F13: O | G13: KBO542 | H13: AXOR 1933 | I13: Cambiar Flexible De Escape | J13: =VLOOKUP(A13,[1]Auditoría!$A$2:$J$312,10,FALSE) -> Falta Consumo | K13: Terminada | L13: 3) Planificado sin Salida física (Salidas = 0) | M13: Materiales planificados con Salida Cero: FLEXIBLE DE TUBO DE ESCAPE MB 1933 (A 958 490 00 65) ORIGINAL | N13: 46234 | O13: 46231
A14: 36373 | B14: Correctivo | C14: BSAS | D14: No | E14: 46198 | F14: O | G14: AF639HB | H14: TECTOR EVO 170E28 | I14: Cambiar Luz De Carroceria | J14: =VLOOKUP(A14,[1]Auditoría!$A$2:$J$312,10,FALSE) -> Falta Consumos | K14: Terminada | L14: 2) Desconexión de material (Falta 'LUZ', 'CARROCERIA') | M14: Materiales cargados no coinciden: CABLE TIPO TALLER DE 2 X 1,5 MM, PRECINTOS GRETEL 400X4,8MM X 100 UNI, TORNILLO AUTOPERFORANTE 8X1 1/4 (PUNTA MECHA) X UN, FUSIBLE 10 AMP - GENROD, FARO LED 48W - 15 X 4 X 5 CM - INFINITY TECH, CINTA AISLADORA NEGRA 19MMx20Mx0.15MM 3M 165 TEMFLEX, FARO LED BAIML 1035 COLOR ROJO, LLAVE 1 PUNTO T/M. BENZ, BALDE GRASA LUBRIGON X 20 KG, ARANDELAS PLANAS DE 6MM | N14: 46234 | O14: 46231
A15: 36373 | B15: Correctivo | C15: BSAS | D15: No | E15: 46198 | F15: O | G15: AF639HB | H15: TECTOR EVO 170E28 | I15: Cambio Tecla De Luz | J15: =VLOOKUP(A15,[1]Auditoría!$A$2:$J$312,10,FALSE) -> Falta Consumos | K15: Terminada | L15: 2) Desconexión de material (Falta 'LUZ') | M15: Materiales cargados no coinciden: CABLE TIPO TALLER DE 2 X 1,5 MM, PRECINTOS GRETEL 400X4,8MM X 100 UNI, TORNILLO AUTOPERFORANTE 8X1 1/4 (PUNTA MECHA) X UN, FUSIBLE 10 AMP - GENROD, FARO LED 48W - 15 X 4 X 5 CM - INFINITY TECH, CINTA AISLADORA NEGRA 19MMx20Mx0.15MM 3M 165 TEMFLEX, FARO LED BAIML 1035 COLOR ROJO, LLAVE 1 PUNTO T/M. BENZ, BALDE GRASA LUBRIGON X 20 KG, ARANDELAS PLANAS DE 6MM | N15: 46234 | O15: 46231
A16: 36604 | B16: Correctivo | C16: BSAS | D16: No | E16: 46198 | F16: O | G16: NIE152 | H16: ATRON 1720 | I16: Cambiar Espejo Lado Der | J16: =VLOOKUP(A16,[1]Auditoría!$A$2:$J$312,10,FALSE) -> Falta Consumos | K16: Terminada | L16: 3) Planificado sin Salida física (Salidas = 0) | M16: Materiales planificados con Salida Cero: ESPEJO DERECHO - (SP 1602) | N16: 46234 | O16: 46231
A17: 36705 | B17: Correctivo | C17: MNZA | D17: No | E17: 46198 | F17: O | G17: GUW657 | H17: 1624 | I17: Colocar Tapa de Cilindro | J17: =VLOOKUP(A17,[1]Auditoría!$A$2:$J$312,10,FALSE) -> Aclarar si es cambio, ver falta Junta tapa de Valvulas | K17: No iniciada | L17: 2) Desconexión de material (Falta 'CILINDRO', 'FUELLE') | M17: Materiales cargados no coinciden: ROTOR NPT 3/4" - CORTO (2361), ARANDELA ALUMINIO 20MM, JUNTA BASE DE RADIADOR DE ACEITE MB 1725 (A 926 188 00 80) - ORIGINAL, ORING DE REFRIGERACION DE ACEITE MB AXOR 1933 (A 000 188 33 80) - PAMPA, CONECTOR BOMBA DE AGUA 904/906 MB 1624/1725 (A 936 203 33 36) ORIGINAL, CORREA 8PK 1380, TENSOR DE CORREA MB 1624 (A 906 200 67 70) ORIGINAL, REGULADOR DE VOLTAJE ALTERNADOR 24V 80 AMP F00M 144 123 BOSCH, FILTRO DE AIRE APU - MANN TB1374/13X, JUEGO DE JUNTA DESCARBONIZACION MB 1933 (A 926 010 35 20) ORIGINAL, LIJA AL AGUA 230x280 GR200, LIJA AL AGUA 230x280 GR120, REPARACION DE COMPRESOR DE AIRE TAPA CORTA(ART. REPARADO), REPARACION DE VALVULA PEDALERA MB 1933/1725 (ART. REPARADO), REPARACION DE VALVULA DE SECADO (ART. REPARADO), CAÑO POLIAMIDA DE 1/2"" X MT, CABLE UNIPOLAR DE 2,5MM X MT, ARANDELA DE ALUMINIO 12MM, PRECINTOS 400X7,2MM X 100 UNI - RODA, PRECINTOS 400X7,2MM X 100 UNI - RODA, LAMPARA 24V 5W (S/CULOTE) - OSRAM, HIDRO ATF B 20 (125480), DESENGRASANTE TRANSNET C SUPER 26K (9503), ARANDELA ALUMINIO 14MM, TERMINAL OJAL DE COBRE ESTAÑADO DE 35MM - BAUD-MOL, THINNER X 18LT, PORTALAMPARA 5W 24V (SIN CABLES), CINTA AISLADORA NEGRA 19MMx20Mx0.15MM 3M 165 TEMFLEX | N17: 46234 | O17: 46231
A18: 36814 | B18: Correctivo | C18: BSAS | D18: No | E18: 46198 | F18: O | G18: OJG099 | H18: ATEGO 1725 | I18: Cambiar lamparas | J18: =VLOOKUP(A18,[1]Auditoría!$A$2:$J$312,10,FALSE) -> Falta Consumo | K18: Terminada | L18: 3) Planificado sin Salida física (Salidas = 0) | M18: Materiales planificados con Salida Cero: LAMPARA 24V 21W | N18: 46234 | O18: 46231
A19: 36816 | B19: Correctivo | C19: BSAS | D19: No | E19: 46198 | F19: O | G19: KBV620 | H19: 1318 | I19: Cambio Tecla De Luz | J19: =VLOOKUP(A19,[1]Auditoría!$A$2:$J$312,10,FALSE) -> Falta Consumo | K19: Terminada | L19: 3) Planificado sin Salida física (Salidas = 0) | M19: Materiales planificados con Salida Cero: TECLA DE LUZ 8 PATAS C/REOSTATO MB 1620 (A 695 545 88 14) - KOSTAL (3040100) | N19: 46234 | O19: 46231
A20: 36817 | B20: Correctivo | C20: BSAS | D20: No | E20: 46198 | F20: O | G20: OJG061 | H20: ATRON 1720 | I20: Cambio Fuelle De Palanca De Cambios | J20: =VLOOKUP(A20,[1]Auditoría!$A$2:$J$312,10,FALSE) -> Falta Material | K20: Terminada | L20: 1) Orden sin repuestos asignados | M20: Ningún material cargado en la orden | N20: 46234 | O20: 46231
A21: 36473 | B21: Correctivo | C21: CIUD | D21: No | E21: 46199 | F21: O | G21: AD426HW | H21: AXOR 2541 | I21: Cambiar Acrilico Trasero MB | J21: =VLOOKUP(A21,[1]Auditoría!$A$2:$J$312,10,FALSE) -> Falta Material | K21: Terminada | L21: 2) Desconexión de material (Falta 'ACRILICO') | M21: Materiales cargados no coinciden: LAMPARA 24V 21W - HELLA, MICA FARO TRASERO MB 2541 (A 002 544 73 90) - FITAM, AZUL 32 UREA x 1000LTS, LAMPARA 24V 5W (C/CULOTE), LAMPARA 24V 21/5W, FILTRO DE HABITACULO MB AXOR 2036 - MANN CU 4469 | N21: 46234 | O21: 46231
A22: 36609 | B22: Correctivo | C22: BSAS | D22: No | E22: 46199 | F22: O | G22: AG300AR | H22: ATEGO 1729 | I22: Cambiar lamparas | J22: =VLOOKUP(A22,[1]Auditoría!$A$2:$J$312,10,FALSE) -> Falta Consumo | K22: Terminada | L22: 3) Planificado sin Salida física (Salidas = 0) | M22: Materiales planificados con Salida Cero: LAMPARA 24V 5W (C/CULOTE) | N22: 46234 | O22: 46231
A23: 36614 | B23: Correctivo | C23: BSAS | D23: No | E23: 46199 | F23: O | G23: AF737MQ | H23: ATEGO 1721 | I23: Cambio Vidrio Espejo | J23: =VLOOKUP(A23,[1]Auditoría!$A$2:$J$312,10,FALSE) -> Falta Consumo | K23: Terminada | L23: 3) Planificado sin Salida física (Salidas = 0) | M23: Materiales planificados con Salida Cero: BARRA TENSORA "V" MB AXOR 1933/2541 (A 942 350 15 05) - IABV (3588), CRISTAL DE ESPEJO IZQ MB 1218/1318 (A 688 725 71 10) - ORIGINAL | N23: 46234 | O23: 46231
A24: 36614 | B24: Correctivo | C24: BSAS | D24: No | E24: 46199 | F24: O | G24: AF737MQ | H24: ATEGO 1721 | I24: Cambiar Lámpara Reglamentarias | J24: =VLOOKUP(A24,[1]Auditoría!$A$2:$J$312,10,FALSE) -> Falta Consumo | K24: Terminada | L24: 3) Planificado sin Salida física (Salidas = 0) | M24: Materiales planificados con Salida Cero: BARRA TENSORA "V" MB AXOR 1933/2541 (A 942 350 15 05) - IABV (3588), CRISTAL DE ESPEJO IZQ MB 1218/1318 (A 688 725 71 10) - ORIGINAL | N24: 46234 | O24: 46231
A25: 36492 | B25: Correctivo | C25: CIUD | D25: No | E25: 46201 | F25: O | G25: AF743LB | H25: ATEGO 1729 | I25: Parametrizar todos los cambios | J25: OK Contabilizar | K25: Terminada | L25: 2) Desconexión de material (Falta 'LONA') | M25: Materiales cargados no coinciden: PRECINTOS GRETEL 200X3,6MM X 100 UNI, CABLE TIPO TALLER DE 3 X 1,5 MM, PRECINTOS 400X7,2MM X 100 UNI - BREMEN, ACEITE 15W40 XV300 X 205LT (TAMBOR), FUSIBLE 15 AMP - GENROD, LAMPARA 24V 5W (C/CULOTE) - NEOLUX, TERMINAL OJAL DE 10MM, ESCOBILLA LIMPIA PARABRISAS 24" - BOSCH (B172), LAMPARA 24V 5W (C/CULOTE) - NEOLUX, REPARACION DE MODULO PLD (ART. REPARADO), TERMINAL OJAL DE 6MM, LAMPARA 24V 21/5W - HELLA, ABRAZADERA PARA COJINETE DE CABINA MB 1418/1725/1726/1721/1729 (A 958 317 01 25) ORIGINAL, PORTA FUSIBLE AEREO - ORO (1057), REPARACION DE MODULO CPC (ART. REPARADO) | N25: 46234
A26: 36494 | B26: Correctivo | C26: CIUD | D26: No | E26: 46201 | F26: O | G26: JKG664 | H26: ATEGO 1725 | I26: Cambio Arandela De Tapa Compresor | J26: =VLOOKUP(A26,[1]Auditoría!$A$2:$J$312,10,FALSE) -> Falta Consumo | K26: Terminada | L26: 2) Desconexión de material (Falta 'COMPRESOR') | M26: Materiales cargados no coinciden: FUSIBLE 10 AMP - GENROD, ARANDELA ALUMINIO 14MM, LIQUIDO REFRIGERANTE KRIOX INORGANICO X 1000LTS, GRASA 62 X 20 KG, PRECINTOS 400X7,2MM X 100 UNI - BREMEN, FAROS LE FM181, FARO - (FM181) - 12714/D - TYC, LAMPARA H7 24V - HELLA, FUSIBLE 10 AMP - GENROD | N26: 46234 | O26: 46231
A27: 36498 | B27: Correctivo | C27: CIUD | D27: No | E27: 46201 | F27: O | G27: OHH596 | H27: ATRON 1720 | I27: Coloco Cubierta Usada TDE - Armado y Desarmado | J27: =VLOOKUP(A27,[1]Auditoría!$A$2:$J$312,10,FALSE) -> Falta Material | K27: Terminada | L27: 2) Desconexión de material (Falta 'NEUMATICO', 'LONA', 'CHAPA') | M27: Materiales cargados no coinciden: TORNILLO FIX 4.5 X 25 | N27: 46234 | O27: 46231
A28: 36848 | B28: Correctivo | C28: BSAS | D28: No | E28: 46201 | F28: O | G28: KNE956 | H28: AXOR 1933 | I28: Colocar Precintos | J28: =VLOOKUP(A28,[1]Auditoría!$A$2:$J$312,10,FALSE) -> Falta Material | K28: Terminada | L28: 1) Orden sin repuestos asignados | M28: Ningún material cargado en la orden | N28: 46234 | O28: 46231
A29: 36503 | B29: Correctivo | C29: CIUD | D29: No | E29: 46202 | F29: O | G29: AF672EU | H29: ATEGO 1729 | I29: Cambiar Lampara de Posicion Delantera Izq | J29: =VLOOKUP(A29,[1]Auditoría!$A$2:$J$312,10,FALSE) -> Falta Material | K29: Terminada | L29: 2) Desconexión de material (Falta 'LAMPARA') | M29: Materiales cargados no coinciden: SIKAFLEX 221 x 600ml (SALCHICHA) | N29: 46234 | O29: 46231
A30: 36629 | B30: Correctivo | C30: CIUD | D30: No | E30: 46202 | F30: O | G30: GDR526 | H30: 1620 | I30: Cambiar Soporte De Alternador | J30: =VLOOKUP(A30,[1]Auditoría!$A$2:$J$312,10,FALSE) -> Falta Material | K30: Terminada | L30: 2) Desconexión de material (Falta 'ALTERNADOR') | M30: Materiales cargados no coinciden: TORNILLO PUNTA DE MECHA (3/8 -14X1") X UN, PRECINTOS DUROLL 400X4,8MM X 100 UNI, TACO DE PARAGOLPE 270x75x75 PARA REMOLQUES - NUGOM, CARRITO DE LONA DOBLE CORREDERA UNIVERSAL (32MM), LAMPARA H1 12V, MARCO FARO DER MB 1620 (A 694 884 72 74) ORIGINAL, SOPORTE DE MOTOR MB 1620 (A 366 150 06 73) ORIGINAL, PARCHE 110 TG (10 U) X CAJA, MANIJA DE PUERTA INTERNA IZQ - MAYREA (56572L), TORNILLO PUNTA DE MECHA (3/8 -14X1") X UN | N30: 46234 | O30: 46231
A31: 36629 | B31: Correctivo | C31: CIUD | D31: No | E31: 46202 | F31: O | G31: GDR526 | H31: 1620 | I31: Cambiar Taco De Carroceria | J31: =VLOOKUP(A31,[1]Auditoría!$A$2:$J$312,10,FALSE) -> Falta Material | K31: Terminada | L31: 2) Desconexión de material (Falta 'CARROCERIA') | M31: Materiales cargados no coinciden: TORNILLO PUNTA DE MECHA (3/8 -14X1") X UN, PRECINTOS DUROLL 400X4,8MM X 100 UNI, TACO DE PARAGOLPE 270x75x75 PARA REMOLQUES - NUGOM, CARRITO DE LONA DOBLE CORREDERA UNIVERSAL (32MM), LAMPARA H1 12V, MARCO FARO DER MB 1620 (A 694 884 72 74) ORIGINAL, SOPORTE DE MOTOR MB 1620 (A 366 150 06 73) ORIGINAL, PARCHE 110 TG (10 U) X CAJA, MANIJA DE PUERTA INTERNA IZQ - MAYREA (56572L), TORNILLO PUNTA DE MECHA (3/8 -14X1") X UN | N31: 46234 | O31: 46231
A32: 36629 | B32: Correctivo | C32: CIUD | D32: No | E32: 46202 | F32: O | G32: GDR526 | H32: 1620 | I32: Colocar Membrana liquida al Techo | J32: =VLOOKUP(A32,[1]Auditoría!$A$2:$J$312,10,FALSE) -> Falta Material | K32: Terminada | L32: 2) Desconexión de material (Falta 'MEMBRANA') | M32: Materiales cargados no coinciden: TORNILLO PUNTA DE MECHA (3/8 -14X1") X UN, PRECINTOS DUROLL 400X4,8MM X 100 UNI, TACO DE PARAGOLPE 270x75x75 PARA REMOLQUES - NUGOM, CARRITO DE LONA DOBLE CORREDERA UNIVERSAL (32MM), LAMPARA H1 12V, MARCO FARO DER MB 1620 (A 694 884 72 74) ORIGINAL, SOPORTE DE MOTOR MB 1620 (A 366 150 06 73) ORIGINAL, PARCHE 110 TG (10 U) X CAJA, MANIJA DE PUERTA INTERNA IZQ - MAYREA (56572L), TORNILLO PUNTA DE MECHA (3/8 -14X1") X UN | N32: 46234 | O32: 46231
A33: 36629 | B33: Correctivo | C33: CIUD | D33: No | E33: 46202 | F33: O | G33: GDR526 | H33: 1620 | I33: Colocar Vaso de Trampa de GasOil | J33: =VLOOKUP(A33,[1]Auditoría!$A$2:$J$312,10,FALSE) -> Falta Material | K33: Terminada | L33: 2) Desconexión de material (Falta 'VENTILADOR VISCOSO', 'GRAMPAS') | M33: Materiales cargados no coinciden: TORNILLO PUNTA DE MECHA (3/8 -14X1") X UN, PRECINTOS DUROLL 400X4,8MM X 100 UNI, TACO DE PARAGOLPE 270x75x75 PARA REMOLQUES - NUGOM, CARRITO DE LONA DOBLE CORREDERA UNIVERSAL (32MM), LAMPARA H1 12V, MARCO FARO DER MB 1620 (A 694 884 72 74) ORIGINAL, SOPORTE DE MOTOR MB 1620 (A 366 150 06 73) ORIGINAL, PARCHE 110 TG (10 U) X CAJA, MANIJA DE PUERTA INTERNA IZQ - MAYREA (56572L), TORNILLO PUNTA DE MECHA (3/8 -14X1") X UN | N33: 46234 | O33: 46231
A34: 36820 | B34: Correctivo | C34: BSAS | D34: No | E34: 46202 | F34: O | G34: OHH586 | H34: ATRON 1720 | I34: Cambiar Tapa De Combustible | J34: =VLOOKUP(A34,[1]Auditoría!$A$2:$J$312,10,FALSE) -> OK Contabilizar | K34: Terminada | L34: 2) Desconexión de material (Falta 'TAPA DE COMBUSTIBLE') | M34: Materiales cargados no coinciden: TAPA DE GASOIL MB UNIVERSAL (TV-4080) - TRINK | N34: 46234 | O34: 46231 | P34: OK
A35: 36821 | B35: Correctivo | C35: BSAS | D35: No | E35: 46202 | F35: O | G35: AF642OS | H35: ATEGO 1721 | I35: Cambiar lamparas | J35: =VLOOKUP(A35,[1]Auditoría!$A$2:$J$312,10,FALSE) -> Falta Consumo | K35: Terminada | L35: 3) Planificado sin Salida física (Salidas = 0) | M35: Materiales planificados con Salida Cero: LAMPARA H7 24V | N35: 46234 | O35: 46231
A36: 36844 | B36: Correctivo | C36: BSAS | D36: No | E36: 46202 | F36: O | G36: OHH592 | H36: ATRON 1720 | I36: Cambiar lampara h1 24v | J36: =VLOOKUP(A36,[1]Auditoría!$A$2:$J$312,10,FALSE) -> Falta Consumo | K36: Terminada | L36: 3) Planificado sin Salida física (Salidas = 0) | M36: Materiales planificados con Salida Cero: LAMPARA H1 24V | N36: 46234 | O36: 46231
A37: 36845 | B37: Correctivo | C37: BSAS | D37: No | E37: 46202 | F37: O | G37: AG095MR | H37: ATEGO 1721 | I37: Cambiar lampara h7 24v | J37: =VLOOKUP(A37,[1]Auditoría!$A$2:$J$312,10,FALSE) -> Falta Consumo | K37: Terminada | L37: 3) Planificado sin Salida física (Salidas = 0) | M37: Materiales planificados con Salida Cero: LAMPARA H7 24V | N37: 46234 | O37: 46231
A38: 36845 | B38: Correctivo | C38: BSAS | D38: No | E38: 46202 | F38: O | G38: AG095MR | H38: ATEGO 1721 | I38: Coloco Brazo Completo De Espejo | J38: =VLOOKUP(A38,[1]Auditoría!$A$2:$J$312,10,FALSE) -> Falta Consumo | K38: Terminada | L38: 3) Planificado sin Salida física (Salidas = 0) | M38: Materiales planificados con Salida Cero: LAMPARA H7 24V | N38: 46234 | O38: 46231
A39: 36846 | B39: Correctivo | C39: BSAS | D39: No | E39: 46202 | F39: O | G39: AF088ED | H39: ATEGO 1726 | I39: Cambiar lampara h7 24v | J39: =VLOOKUP(A39,[1]Auditoría!$A$2:$J$312,10,FALSE) -> Falta Consumo | K39: Terminada | L39: 3) Planificado sin Salida física (Salidas = 0) | M39: Materiales planificados con Salida Cero: LAMPARA H7 24V | N39: 46234 | O39: 46231
A40: 36867 | B40: Correctivo | C40: BSAS | D40: No | E40: 46202 | F40: O | G40: KAV644 | H40: ATEGO 1418 | I40: Cambiar Lampara De Giro | J40: =VLOOKUP(A40,[1]Auditoría!$A$2:$J$312,10,FALSE) -> Falta Consumo | K40: Terminada | L40: 3) Planificado sin Salida física (Salidas = 0) | M40: Materiales planificados con Salida Cero: LAMPARA 24V 21W | N40: 46234 | O40: 46231
...
