Workbook

Sheet Auditoría
A1: Nro. Orden | B1: Tipo de orden | C1: Centros de costos | D1: Estado Orden | E1: Contabilizada | F1: Fecha de la orden | G1: Status de documento | H1: Equipo | I1: Nombre Equipo | J1: Tarea | K1: Control | L1: Repuestas. | M1: Estado Tarea | N1: Tipo de Hallazgo | O1: Detalle | P1: Resultado IA | Q1: Material Relacionado | R1: Confianza IA | S1: Justificación IA | T1: Descarga | U1: Estados Control | V1: Estados OK
A2: 39046 | B2: Correctivo | C2: CIUD | D2: Liberada | E2: No | F2: 46246 | G2: O | H2: FGV321 | I2: 1218 | J2: Agregar Aceite | K2: =VLOOKUP(A2,[1]Auditoría!$A$2:$L$120,11,FALSE) -> Falta Consumo | M2: Terminada | N2: 3) Planificado sin Salida física (Salidas = 0) | O2: Materiales planificados con Salida Cero: GRASA 62 X 20 KG, LAMPARA 24V 21W - NEOLUX, ACEITE 15W40 XV300 X 205LT (TAMBOR) | T2: 46248 | U2: 46247
A3: 39115 | B3: Correctivo | C3: CIUD | D3: Liberada | E3: No | F3: 46242 | G3: O | H3: AD367PX | I3: S.A.P.3E.71 | J3: Lubricar Carritos De Lonas Y Parantes | K3: Ok | M3: No iniciada | N3: 1) Orden sin repuestos asignados | O3: Ningún material cargado en la orden | T3: 46248
A4: 38694 | B4: Correctivo | C4: CIUD | D4: Liberada | E4: No | F4: 46235 | G4: O | H4: OIC419 | I4: ATRON 1720 | J4: Cambiar Lamparas 24V 5W Varias | K4: Falta Consumo | M4: Terminada | N4: 3) Planificado sin Salida física (Salidas = 0) | O4: Materiales planificados con Salida Cero: FUSIBLE 10 AMP - GENROD, LAMPARA 24V 5W (S/CULOTE) - NEOLUX | T4: 46248
A5: 38431 | B5: Correctivo | C5: SRAF | D5: Liberada | E5: No | F5: 46238 | G5: O | H5: LFK337 | I5: AXOR 2035 | J5: Agregar liquido refrigerante | K5: =VLOOKUP(A5,[1]Auditoría!$A$2:$L$120,11,FALSE) -> Falta Consumo | M5: No iniciada | N5: 3) Planificado sin Salida física (Salidas = 0) | O5: Materiales planificados con Salida Cero: LIQUIDO REFRIGERANTE KRIOX INORGANICO X 1000LTS, ACEITE 15W40 XV300 X 205LT (TAMBOR) | T5: 46248 | U5: 46247
A6: 38994 | B6: Correctivo | C6: SRAF | D6: Liberada | E6: No | F6: 46245 | G6: O | H6: BRJ211 | I6: 710 | J6: Cambiar Fusible 15 Amp | K6: Falta Consumo | M6: No iniciada | N6: 3) Planificado sin Salida física (Salidas = 0) | O6: Materiales planificados con Salida Cero: FUSIBLE 15 AMP - GENROD, RELAY 5 PATAS 12V | T6: 46248
A7: 39002 | B7: Correctivo | C7: SRAF | D7: Liberada | E7: No | F7: 46246 | G7: O | H7: KUF609 | I7: AXOR 1933 | J7: Cambiar sensor de presion de aceite | K7: Falta Consumo | M7: No iniciada | N7: 3) Planificado sin Salida física (Salidas = 0) | O7: Materiales planificados con Salida Cero: SENSOR DE PRESION DE ACEITE MB AXOR 1933 (A 011 153 92 28) ORIGINAL | T7: 46248 | U7: 46247
A8: 39128 | B8: Correctivo | C8: CIUD | D8: Liberada | E8: No | F8: 46244 | G8: O | H8: AF066NS | I8: TECTOR EVO 170E28 | J8: Cambiar Rueda Completa C/Llanta Delantera Der | K8: Falta Consumo | M8: No iniciada | N8: 3) Planificado sin Salida física (Salidas = 0) | O8: Materiales planificados con Salida Cero: CUBIERTA LINEAL 275 R22.5 - FATE | T8: 46248
A9: 38411 | B9: Correctivo | C9: MNZA | D9: Liberada | E9: No | F9: 46237 | G9: O | H9: LUW863 | I9: ACOPLADO BARANDA VOLC. 3 EJES | J9: Cambiar Cubierta 3DI | K9: =VLOOKUP(A9,[1]Auditoría!$A$2:$L$120,11,FALSE) -> Falta Consumo | M9: Terminada | N9: 3) Planificado sin Salida física (Salidas = 0) | O9: Materiales planificados con Salida Cero: RECAPADO NEUMATICO 295 | T9: 46248 | U9: 46247
A10: 38532 | B10: Preventivo | C10: SRAF | D10: Liberada | E10: No | F10: 46237 | G10: O | H10: KUF609 | I10: AXOR 1933 | J10: Cambio De Filtro Gas Oíl Y Trampa De Agua | K10: =VLOOKUP(A10,[1]Auditoría!$A$2:$L$120,11,FALSE) -> Falta Consumo | M10: No iniciada | N10: 3) Planificado sin Salida física (Salidas = 0) | O10: Materiales planificados con Salida Cero: FILTRO TRAMPA DE AGUA - WIX (WF 10288), FILTRO DE COMBUSTIBLE - MANN PU1046/1X | T10: 46248 | U10: 46247
A11: 39155 | B11: Correctivo | C11: CIUD | D11: Liberada | E11: No | F11: 46245 | G11: O | H11: AF461DA | I11: PALETERO S.PA.3E.71 2+1 | J11: Cambiar Fusible 10 Amp | K11: Falta Consumo | M11: No iniciada | N11: 3) Planificado sin Salida física (Salidas = 0) | O11: Materiales planificados con Salida Cero: FUSIBLE 10 AMP - GENROD | T11: 46248
A12: 39235 | B12: Correctivo | C12: CIUD | D12: Liberada | E12: No | F12: 46247 | G12: O | H12: AF118QB | I12: ATEGO 1729 | J12: Engrase tractor completo | K12: Falta Material (315) | M12: No iniciada | N12: 1) Orden sin repuestos asignados | O12: Ningún material cargado en la orden | T12: 46248
A13: 38964 | B13: Correctivo | C13: CIUD | D13: Cerrada | E13: No | F13: 46244 | G13: O | H13: KDG188 | I13: 1318 | J13: Engrase tractor completo | K13: =VLOOKUP(A13,[1]Auditoría!$A$2:$L$120,11,FALSE) -> Falta Material (315) | M13: Terminada | N13: 2) Falta material (IA) | O13: Tarea de lubricación sin material de grasa, aceite o refrigerante en la orden | T13: 46248 | U13: 46247
A14: 38534 | B14: Correctivo | C14: SRAF | D14: Liberada | E14: No | F14: 46239 | G14: O | H14: MQU466 | I14: SCANIA P360 A6X2 | J14: Cambiar junta de compresor de aire | K14: =VLOOKUP(A14,[1]Auditoría!$A$2:$L$120,11,FALSE) -> Falta Material | M14: No iniciada | N14: 1) Orden sin repuestos asignados | O14: Ningún material cargado en la orden | T14: 46248 | U14: 46247
A15: 39010 | B15: Correctivo | C15: SRAF | D15: Liberada | E15: No | F15: 46245 | G15: O | H15: IBB073 | I15: S PA 3E 71 | J15: Engrase Completo | K15: =VLOOKUP(A15,[1]Auditoría!$A$2:$L$120,11,FALSE) -> Falta Material | M15: No iniciada | N15: 1) Orden sin repuestos asignados | O15: Ningún material cargado en la orden | T15: 46248 | U15: 46247
A16: 38431 | B16: Correctivo | C16: SRAF | D16: Liberada | E16: No | F16: 46238 | G16: O | H16: LFK337 | I16: AXOR 2035 | J16: Colocar inyectores y bomba inyectora | K16: =VLOOKUP(A16,[1]Auditoría!$A$2:$L$120,11,FALSE) -> Falta Consumo | M16: No iniciada | N16: 3) Planificado sin Salida física (Salidas = 0) | O16: Materiales planificados con Salida Cero: LIQUIDO REFRIGERANTE KRIOX INORGANICO X 1000LTS, ACEITE 15W40 XV300 X 205LT (TAMBOR) | T16: 46248 | U16: 46247
A17: 38932 | B17: Correctivo | C17: CIUD | D17: Liberada | E17: No | F17: 46241 | G17: O | H17: AB320YW | I17: ATEGO 2426 | J17: Cambiar Lamparas 24V 21/5w Varias | K17: =VLOOKUP(A17,[1]Auditoría!$A$2:$L$120,11,FALSE) -> Falta Consumo | M17: Terminada | N17: 3) Planificado sin Salida física (Salidas = 0) | O17: Materiales planificados con Salida Cero: LAMPARA 24V 21W | T17: 46248 | U17: 46247
A18: 38936 | B18: Correctivo | C18: CIUD | D18: Cerrada | E18: No | F18: 46241 | G18: O | H18: AD426IJ | I18: AXOR 2541 | J18: Engraso Plato | K18: =VLOOKUP(A18,[1]Auditoría!$A$2:$L$120,11,FALSE) -> Falta Material (315) | M18: Terminada | N18: 1) Orden sin repuestos asignados | O18: Ningún material cargado en la orden | T18: 46248 | U18: 46247
A19: 38606 | B19: Correctivo | C19: SRAF | D19: Liberada | E19: No | F19: 46241 | G19: O | H19: KUF609 | I19: AXOR 1933 | J19: Agregar liquido refrigerante | K19: =VLOOKUP(A19,[1]Auditoría!$A$2:$L$120,11,FALSE) -> Falta Consumo | M19: No iniciada | N19: 3) Planificado sin Salida física (Salidas = 0) | O19: Materiales planificados con Salida Cero: FARO TRAS DER MB 2035 AXOR (A 002 544 12 90) - MARSTECH, LIQUIDO REFRIGERANTE KRIOX INORGANICO X 1000LTS | T19: 46248 | U19: 46247
A20: 38664 | B20: Correctivo | C20: CIUD | D20: Cerrada | E20: No | F20: 46237 | G20: O | H20: AD426HY | I20: AXOR 2541 | J20: Cambiar Lamparas 24V 21/5w Varias | K20: =VLOOKUP(A20,[1]Auditoría!$A$2:$L$120,11,FALSE) -> Falta Material | M20: Terminada | N20: 1) Orden sin repuestos asignados | O20: Ningún material cargado en la orden | T20: 46248 | U20: 46247
A21: 39130 | B21: Correctivo | C21: CIUD | D21: Liberada | E21: No | F21: 46244 | G21: O | H21: OHH591 | I21: ATRON 1720 | J21: Lubricar Carritos De Lonas Y Parantes | K21: Ok | M21: No iniciada | N21: 1) Orden sin repuestos asignados | O21: Ningún material cargado en la orden | T21: 46248
A22: 39151 | B22: Correctivo | C22: CIUD | D22: Liberada | E22: No | F22: 46245 | G22: O | H22: AD426IJ | I22: AXOR 2541 | J22: Cambiar lampara h3 24v | K22: Falta Material | M22: No iniciada | N22: 1) Orden sin repuestos asignados | O22: Ningún material cargado en la orden | T22: 46248
A23: 39233 | B23: Correctivo | C23: CIUD | D23: Liberada | E23: No | F23: 46247 | G23: O | H23: AF371BH | I23: PALETERO S.PA.3E.71 2+1 | J23: Cambiar Faro Led 1010E | K23: Falta Consumo | M23: Terminada | N23: 3) Planificado sin Salida física (Salidas = 0) | O23: Materiales planificados con Salida Cero: BALDE GRASA LUBRIGON X 20 KG, FARO LED COMPLETO (C/FICHA) BAIML 1010E (AMBAR) | T23: 46248
A24: 38860 | B24: Correctivo | C24: CIUD | D24: Liberada | E24: No | F24: 46239 | G24: O | H24: OJG098 | I24: ATEGO 1725 | J24: Cambiar lampara 5w 24v | K24: =VLOOKUP(A24,[1]Auditoría!$A$2:$L$120,11,FALSE) -> Falta Consumo | M24: Terminada | N24: 3) Planificado sin Salida física (Salidas = 0) | O24: Materiales planificados con Salida Cero: LAMPARA 24V 5W (S/CULOTE) | T24: 46248 | U24: 46247
A25: 38606 | B25: Correctivo | C25: SRAF | D25: Liberada | E25: No | F25: 46241 | G25: O | H25: KUF609 | I25: AXOR 1933 | J25: Agregar Aceite (Tractor) | K25: =VLOOKUP(A25,[1]Auditoría!$A$2:$L$120,11,FALSE) -> Falta Consumo | M25: No iniciada | N25: 3) Planificado sin Salida física (Salidas = 0) | O25: Materiales planificados con Salida Cero: FARO TRAS DER MB 2035 AXOR (A 002 544 12 90) - MARSTECH, LIQUIDO REFRIGERANTE KRIOX INORGANICO X 1000LTS | T25: 46248 | U25: 46247
A26: 39129 | B26: Correctivo | C26: CIUD | D26: Liberada | E26: No | F26: 46244 | G26: O | H26: AF642OU | I26: ATEGO 1721 | J26: Colocar Llave de 1 Punto | K26: Falta Consumo | M26: No iniciada | N26: 3) Planificado sin Salida física (Salidas = 0) | O26: Materiales planificados con Salida Cero: LLAVE 1 PUNTO T/M. BENZ | T26: 46248
A27: 39113 | B27: Correctivo | C27: CIUD | D27: Liberada | E27: No | F27: 46242 | G27: O | H27: AD426HX | I27: AXOR 2541 | J27: Cambiar comando levanta vidrio | K27: Falta Material | M27: No iniciada | N27: 1) Orden sin repuestos asignados | O27: Ningún material cargado en la orden | T27: 46248
A28: 38694 | B28: Correctivo | C28: CIUD | D28: Liberada | E28: No | F28: 46235 | G28: O | H28: OIC419 | I28: ATRON 1720 | J28: Cambiar Fusible 10 Amp | K28: Falta Consumo | M28: Terminada | N28: 3) Planificado sin Salida física (Salidas = 0) | O28: Materiales planificados con Salida Cero: FUSIBLE 10 AMP - GENROD, LAMPARA 24V 5W (S/CULOTE) - NEOLUX | T28: 46248
A29: 38441 | B29: Correctivo | C29: SRAF | D29: Liberada | E29: No | F29: 46238 | G29: O | H29: FQT894 | I29: 1620 | J29: Cambiar bombin de embrague | K29: =VLOOKUP(A29,[1]Auditoría!$A$2:$L$120,11,FALSE) -> Falta Consumo | M29: No iniciada | N29: 3) Planificado sin Salida física (Salidas = 0) | O29: Materiales planificados con Salida Cero: BOMBIN INFERIOR DE EMBRAGUE MB 1620 (A 386 295 72 07) - TRW | T29: 46248 | U29: 46247
A30: 38998 | B30: Correctivo | C30: CIUD | D30: Cerrada | E30: No | F30: 46245 | G30: O | H30: AF613YX | I30: TECTOR EVO 170E28 | J30: Lubricar Guia De Lona y Regulo | K30: Ok | M30: Terminada | N30: 2) Falta material (IA) | O30: Tarea de lubricación sin material de grasa, aceite o refrigerante en la orden | T30: 46248 | U30: 46247
A31: 38574 | B31: Preventivo | C31: CIUD | D31: Liberada | E31: No | F31: 46240 | G31: O | H31: AF743LB | I31: ATEGO 1729 | J31: Cambiar filtro de aire | K31: =VLOOKUP(A31,[1]Auditoría!$A$2:$L$120,11,FALSE) -> Falta Consumo | M31: Terminada | N31: 3) Planificado sin Salida física (Salidas = 0) | O31: Materiales planificados con Salida Cero: FILTRO DE AIRE MB 2426/AXOR 1933 - MANN C28 1012 | T31: 46248 | U31: 46247
A32: 38612 | B32: Correctivo | C32: SRAF | D32: Liberada | E32: No | F32: 46241 | G32: O | H32: OAF643 | I32: G310 | J32: Agregar Aceite (Tractor) | K32: =VLOOKUP(A32,[1]Auditoría!$A$2:$L$120,11,FALSE) -> Falta Material | M32: No iniciada | N32: 1) Orden sin repuestos asignados | O32: Ningún material cargado en la orden | T32: 46248 | U32: 46247
A33: 39046 | B33: Correctivo | C33: CIUD | D33: Liberada | E33: No | F33: 46246 | G33: O | H33: FGV321 | I33: 1218 | J33: Engrase tractor completo | K33: =VLOOKUP(A33,[1]Auditoría!$A$2:$L$120,11,FALSE) -> Falta Consumo | M33: Terminada | N33: 3) Planificado sin Salida física (Salidas = 0) | O33: Material de lubricante planificado con Salida Cero: GRASA 62 X 20 KG, ACEITE 15W40 XV300 X 205LT (TAMBOR) | T33: 46248 | U33: 46247
A34: 38411 | B34: Correctivo | C34: MNZA | D34: Liberada | E34: No | F34: 46237 | G34: O | H34: LUW863 | I34: ACOPLADO BARANDA VOLC. 3 EJES | J34: Cambiar Cubierta 3II | K34: =VLOOKUP(A34,[1]Auditoría!$A$2:$L$120,11,FALSE) -> Falta Consumo | M34: Terminada | N34: 3) Planificado sin Salida física (Salidas = 0) | O34: Materiales planificados con Salida Cero: RECAPADO NEUMATICO 295 | T34: 46248 | U34: 46247
A35: 38431 | B35: Correctivo | C35: SRAF | D35: Liberada | E35: No | F35: 46238 | G35: O | H35: LFK337 | I35: AXOR 2035 | J35: Agregar Aceite (Tractor) | K35: =VLOOKUP(A35,[1]Auditoría!$A$2:$L$120,11,FALSE) -> Falta Consumo | M35: No iniciada | N35: 3) Planificado sin Salida física (Salidas = 0) | O35: Materiales planificados con Salida Cero: LIQUIDO REFRIGERANTE KRIOX INORGANICO X 1000LTS, ACEITE 15W40 XV300 X 205LT (TAMBOR) | T35: 46248 | U35: 46247
A36: 38994 | B36: Correctivo | C36: SRAF | D36: Liberada | E36: No | F36: 46245 | G36: O | H36: BRJ211 | I36: 710 | J36: Cambiar relay | K36: Falta Consumo | M36: No iniciada | N36: 3) Planificado sin Salida física (Salidas = 0) | O36: Materiales planificados con Salida Cero: FUSIBLE 15 AMP - GENROD, RELAY 5 PATAS 12V | T36: 46248
A37: 39002 | B37: Correctivo | C37: SRAF | D37: Liberada | E37: No | F37: 46246 | G37: O | H37: KUF609 | I37: AXOR 1933 | J37: Engrase Completo | K37: Falta Consumo | M37: No iniciada | N37: 3) Planificado sin Salida física (Salidas = 0) | O37: Material de lubricante planificado con Salida Cero: SENSOR DE PRESION DE ACEITE MB AXOR 1933 (A 011 153 92 28) ORIGINAL | T37: 46248 | U37: 46247
A38: 39046 | B38: Correctivo | C38: CIUD | D38: Liberada | E38: No | F38: 46246 | G38: O | H38: FGV321 | I38: 1218 | J38: Cambiar lamparas | K38: =VLOOKUP(A38,[1]Auditoría!$A$2:$L$120,11,FALSE) -> Falta Consumo | M38: Terminada | N38: 3) Planificado sin Salida física (Salidas = 0) | O38: Materiales planificados con Salida Cero: GRASA 62 X 20 KG, LAMPARA 24V 21W - NEOLUX, ACEITE 15W40 XV300 X 205LT (TAMBOR) | T38: 46248 | U38: 46247
A39: 38531 | B39: Preventivo | C39: SRAF | D39: Liberada | E39: No | F39: 46239 | G39: O | H39: KUF609 | I39: AXOR 1933 | J39: Cambio De Aceite De Motor Y Filtro Aceite | K39: =VLOOKUP(A39,[1]Auditoría!$A$2:$L$120,11,FALSE) -> Falta Consumo | M39: No iniciada | N39: 3) Planificado sin Salida física (Salidas = 0) | O39: Materiales planificados con Salida Cero: FILTRO DE ACEITE 6 CILINDROS MB 1725/1726/1933/1624L/1721 OF ELECTRONICO - MANN HU 945/2x, ACEITE 15W40 XV300 X 205LT (TAMBOR) | T39: 46248 | U39: 46247
A40: 38612 | B40: Correctivo | C40: SRAF | D40: Liberada | E40: No | F40: 46241 | G40: O | H40: OAF643 | I40: G310 | J40: Engrase Completo | K40: =VLOOKUP(A40,[1]Auditoría!$A$2:$L$120,11,FALSE) -> Falta Material | M40: No iniciada | N40: 1) Orden sin repuestos asignados | O40: Ningún material cargado en la orden | T40: 46248 | U40: 46247
...
